UNEXPECTED: int. Recover by rethrowing a bool.
Caught bool: 0
UNEXPECTED: foo_exception. No recovery is possible.
terminate called after throwing an instance of 'std::runtime_error'
  what():  foo_exception
./cmd.sh: line 1: 15936 Aborted                 (core dumped) ./a.out
