terminate called after throwing an instance of 'std::out_of_range'
  what():  vector::_M_range_check
1 0
2 0
3 0
4 0
5 0
6 18446744073709551611
7 18446744073709551610
8 18446744073709551610
9 18446744073709551610
10 18446744073709551610
bash: line 7: 18511 Aborted                 (core dumped) ./a.out
