terminate called after throwing an instance of 'std::bad_function_call'
  what():  std::exception
/tmp/compile.sh: line 6: 19776 Aborted                 (core dumped) ./test > .stdout
2
