Logic_error vector::_M_range_check: __n (which is 10) >= this->size() (which is 1)
terminate called after throwing an instance of 'std::out_of_range'
  what():  vector::_M_range_check: __n (which is 10) >= this->size() (which is 1)
bash: line 7: 30991 Aborted                 (core dumped) ./a.out
