terminate called after throwing an instance of 'std::runtime_error'
  what():  Some error
bash: line 7: 18339 Aborted                 (core dumped) ./a.out
