main.cpp(29): Throw in function int main()
Dynamic exception type: boost::exception_detail::clone_impl<my_exception4>
std::exception::what: (empty)

